Workbook

Sheet Combined All Plant
A1: RMC Batching Plant Jaypee Wish Town – Monthly Overheads Report
A2: ALL PLANTS COMBINED (KRH & GDI) | D2: Month & Year: MARCH 2026
A3: Prepared by: Reetesh Sharma, Manager - Quality | D3: Submitted to (for review): Jitendra Sir, Mukesh Mokha Sir
A5: 1. Machinery Overhead
A6: Equipment | B6: Qty | C6: Rate/Month (₹) | D6: Total Cost (₹) | E6: Remarks
A7: Batching Plant (Main Unit) | B7: =KRH!B7+'GDI PLANT'!B7 -> 2 | D7: 0 | E7: Company Owned Plant
A8: Transit Mixers (TMs) | B8: =KRH!B8+'GDI PLANT'!B8 -> 14 | C8: =KRH!C8+'GDI PLANT'!C8 -> 139705.95 | D8: =KRH!D8+'GDI PLANT'!D8 -> 1955883.3 | E8: Rented TMs- Shared Resources, used interchangeably at both plants. Final cost amount not yet confirmed as breakdown deduction to be done from this amount
A9: JCB | B9: =KRH!B9+'GDI PLANT'!B9 -> 1 | C9: =KRH!C9+'GDI PLANT'!C9 -> 0 | D9: =KRH!D9+'GDI PLANT'!D9 -> 155760 | E9: JCB not Deployed at KRH
A10: Loader | B10: =KRH!B10+'GDI PLANT'!B10 -> 1 | C10: =KRH!C10+'GDI PLANT'!C10 -> 153400 | D10: =KRH!D10+'GDI PLANT'!D10 -> 153400 | E10: Rented Loader
A11: Concrete Pumps | B11: =KRH!B11+'GDI PLANT'!B11 -> 0 | C11: =KRH!C11+'GDI PLANT'!C11 -> 0 | D11: =KRH!D11+'GDI PLANT'!D11 -> 0 | E11: Pump not deployed at KRH in March
A12: Maintenance & Spares | D12: =KRH!D12+'GDI PLANT'!D12 -> 636048 | E12: Mostly used for Bottom Tiles, Shovel etc. for Plant Mixer at KRH
A13: Total Machinery Overhead | D13: =SUM(D7:D12) -> 2901091.3
A15: 2. Fuel and Lubricant Overheads
A16: Description | B16: Consumption (Litres) | C16: TOTAL PRODUCTION (IN CuM.) | D16: AVERAGE FUEL CONSUMPTION (IN LITRES PER CuM.) | E16: Rate of Fuel (₹/Litre) | F16: Total Cost (₹) | G16: Fuel Cost per CuM. (₹)
A17: Diesel – TMs (Shared Resources, used interchangeably at both plants) | B17: =KRH!B17+'GDI PLANT'!B17 -> 13660 | C17: =KRH!C17+'GDI PLANT'!C17 -> 7698 | D17: =B21/C17 -> 2.1044427 | E17: 88.05 | F17: =E17*B21 -> 1426410 | G17: =F17/C17 -> 185.29618
A18: Diesel – JCB | B18: =KRH!B18+'GDI PLANT'!B18 -> 1300
A19: Diesel – LOADER | B19: =KRH!B19+'GDI PLANT'!B19 -> 1220
A20: Diesel – DG | B20: =KRH!B20+'GDI PLANT'!B20 -> 20
A21: Total Fuel Overhead | B21: =SUM(B17:B20) -> 16200
A23: 3. Raw Material Overheads
A24: Material | B24: Avg. Cost per MT (₹) | C24: Monthly Quantity Consumed (MT) | D24: Total Cost (₹) | E24: Raw Material Cost Per CuM. (₹) | F24: Remarks
A25: Cement | B25: 6619.99 | C25: =KRH!C25+'GDI PLANT'!C25 -> 2035.83 | D25: =B25*C25 -> 13477174 | E25: =D32/C17 -> 4640.3565
A26: 20mm Aggregate | B26: =1280+5%*1280 -> 1344 | C26: =KRH!C26+'GDI PLANT'!C26 -> 4445 | D26: =B26*C26 -> 5974080
A27: 10mm Aggregate | B27: =1245+5%*1245 -> 1307.25 | C27: =KRH!C27+'GDI PLANT'!C27 -> 4252 | D27: =B27*C27 -> 5558427
A28: Fine Aggregate | B28: =1235+5%*1235 -> 1296.75 | C28: =KRH!C28+'GDI PLANT'!C28 -> 6490 | D28: =B28*C28 -> 8415907.5
A29: Fly Ash | B29: =1275+5%*1275 -> 1338.75 | C29: =KRH!C29+'GDI PLANT'!C29 -> 1001.82 | D29: =B29*C29 -> 1341186.5
A30: Admixtures | B30: 53000 | C30: =KRH!C30+'GDI PLANT'!C30 -> 18.013 | D30: =B30*C30 -> 954689
A31: Water Tanker | C31: =KRH!C31+'GDI PLANT'!C31 -> 0 | D31: =B31*C31 -> 0
A32: Total Raw Material Overhead | D32: =SUM(D25:D31) -> 35721464
A34: 4. Manpower Overhead (Labour Expenses)
A35: Category | C35: No. of Persons | D35: Total Cost (₹) | E35: Details of Personnel Deployed | F35: Manpower Cost Per CuM. (₹)
A36: Maintenance & Electrical Team | C36: =KRH!C36+'GDI PLANT'!C36 -> 1 | D36: =KRH!D36+'GDI PLANT'!D36 -> 34000 | E36: Rohit, Pramod | F36: =D43/C17 -> 134.64692
A37: Quality Team | C37: =KRH!C37+'GDI PLANT'!C37 -> 5 | D37: =KRH!D37+'GDI PLANT'!D37 -> 226000 | E37: Vikas, Sandeep, Manoj, Joginder, Golu
A38: Batching Plant Operator | C38: =KRH!C38+'GDI PLANT'!C38 -> 3 | D38: =KRH!D38+'GDI PLANT'!D38 -> 104000 | E38: Bhola, Jitin
A39: Production Supervision Team | C39: =KRH!C39+'GDI PLANT'!C39 -> 4 | D39: =KRH!D39+'GDI PLANT'!D39 -> 226000 | E39: Suraj, Sangat, Rajesh
A40: Helper / Unskilled Labour | D40: =KRH!D40+'GDI PLANT'!D40 -> 446512 | E40: Deployed on part of the labour contractor
A41: JCB & Loader Operator | C41: =KRH!C41+'GDI PLANT'!C41 -> 0 | E41: Deployed on part of the vendor
A42: Housekeeping / Office Staff | C42: =KRH!C42+'GDI PLANT'!C42 -> 0 | E42: Not deployed
A43: Total Manpower Overhead | D43: =SUM(D36:D42) -> 1036512
A45: 5. Electricity and Power Overheads
...

Sheet KRH
A1: RMC Batching Plant – Monthly Overheads Report
A2: Plant Name: KRH PLANT | D2: Month & Year: MARCH 2026
A3: Prepared by: Reetesh Sharma, Manager - Quality | D3: Submitted to (for review): Jitendra Sir, Mukesh Mokha Sir
A5: 1. Machinery Overhead
A6: Equipment | B6: Qty | C6: Rate/Month (₹) | D6: Total Cost (₹) | E6: Remarks
A7: Batching Plant (Main Unit) | B7: 1 | D7: 0 | E7: Company Owned Plant
A8: Transit Mixers (TMs) | B8: 14 | C8: =D8/B8 -> 139705.95 | D8: =(256935)+(0.18*256935)+(125000*5)+(0.18*125000)+(140000*7)+(0.18*140000) -> 1955883.3 | E8: Rented TMs- Shared Resources, used interchangeably at both plants. Final cost amount not yet confirmed as breakdown deduction to be done from this amount
A9: JCB | B9: 0 | D9: 0 | E9: JCB not Deployed at KRH
A10: Loader | B10: 1 | C10: =130000+(0.18*130000) -> 153400 | D10: =B10*C10 -> 153400 | E10: Rented Loader
A11: Concrete Pumps | B11: 0 | D11: 0 | E11: Pump not deployed at KRH in March
A12: Maintenance & Spares | D12: =636048-185000 -> 451048 | E12: Mostly used for Bottom Tiles, Shovel etc. for Plant Mixer at KRH
A13: Total Machinery Overhead | D13: =SUM(D7:D12) -> 2560331.3
A15: 2. Fuel and Lubricant Overheads
A16: Description | B16: Consumption (Litres) | C16: TOTAL PRODUCTION (IN CuM.) | D16: AVERAGE FUEL CONSUMPTION (IN LITRES PER CuM.) | E16: Rate of Fuel (₹/Litre) | F16: Total Cost (₹) | G16: Fuel Cost per CuM. (₹)
A17: Diesel – TMs (Shared Resources, used interchangeably at both plants) | B17: =13640+20 -> 13660 | C17: 5926 | D17: =B21/C17 -> 2.5143436 | E17: 88.05 | F17: =E17*B21 -> 1311945 | G17: =F17/C17 -> 221.38795
A18: Diesel – JCB | B18: 0
A19: Diesel – LOADER | B19: 1220
A20: Diesel – DG | B20: 20
A21: Total Fuel Overhead | B21: =SUM(B17:B20) -> 14900
A23: 3. Raw Material Overheads
A24: Material | B24: Avg. Cost per MT (₹) | C24: Monthly Quantity Consumed (MT) | D24: Total Cost (₹) | E24: Raw Material Cost Per CuM. (₹) | F24: Remarks
A25: Cement | B25: 6619.99 | C25: 1593.7 | D25: =B25*C25 -> 10550278 | E25: =D32/C17 -> 4587.1851
A26: 20mm Aggregate | B26: =1280+5%*1280 -> 1344 | C26: =3434 -> 3434 | D26: =B26*C26 -> 4615296
A27: 10mm Aggregate | B27: =1245+5%*1245 -> 1307.25 | C27: 3336 | D27: =B27*C27 -> 4360986
A28: Fine Aggregate | B28: =1235+5%*1235 -> 1296.75 | C28: 5084 | D28: =B28*C28 -> 6592677
A29: Fly Ash | B29: =1275+5%*1275 -> 1338.75 | C29: 794.52 | D29: =B29*C29 -> 1063663.6
A30: Admixtures | B30: 53 | C30: 14.3 | D30: =B30*C30 -> 757.9
A31: Water Tanker | C31: 0 | D31: =B31*C31 -> 0
A32: Total Raw Material Overhead | D32: =SUM(D25:D31) -> 27183659
A34: 4. Manpower Overhead (Labour Expenses)
A35: Category | C35: No. of Persons | D35: Total Cost (₹) | E35: Details of Personnel Deployed | F35: Manpower Cost Per CuM. (₹)
A36: Maintenance & Electrical Team | C36: 1 | D36: =34000 -> 34000 | E36: Rohit | F36: =D43/C17 -> 168.1593
A37: Quality Team | C37: 5 | D37: =90000+53000+28000+33000+22000 -> 226000 | E37: Vikas, Sandeep, Manoj, Joginder, Golu
A38: Batching Plant Operator | C38: 2 | D38: =32000+32000 -> 64000 | E38: Bhola, Jitin
A39: Production Supervision Team | C39: 4 | D39: =134000+28000+32000+32000 -> 226000 | E39: Vitul, Suraj, Sangat, Rajesh
A40: Helper / Unskilled Labour | D40: 446512 | E40: Deployed on part of the labour contractor | H40: =474/31 -> 15.290323
A41: JCB & Loader Operator | C41: 0 | E41: Deployed on part of the vendor
A42: Housekeeping / Office Staff | C42: 0 | E42: Not deployed
A43: Total Manpower Overhead | D43: =SUM(D36:D40) -> 996512
A45: 5. Electricity and Power Overheads
...

Sheet GDI PLANT
A1: RMC Batching Plant – Monthly Overheads Report
A2: Plant Name: GDI PLANT | D2: Month & Year: MARCH 2026
A3: Prepared by: Reetesh Sharma, Manager - Quality | D3: Submitted to (for review): Jitendra Sir, Mukesh Mokha Sir
A5: 1. Machinery Overhead
A6: Equipment | B6: Qty | C6: Rate/Month (₹) | D6: Total Cost (₹) | E6: Remarks
A7: Batching Plant (Main Unit) | B7: 1 | D7: 0 | E7: Company Owned Plant
A8: Transit Mixers (TMs) | B8: 0 | D8: 0 | E8: Rented TMs- Shared Resources, used interchangeably at both plants. Final cost amount not yet confirmed as breakdown deduction to be done from this amount
A9: JCB | B9: 1 | D9: 155760 | E9: Rented JCB deployed at GDI
A10: Loader | B10: 0 | D10: =B10*C10 -> 0 | E10: Not Deployed
A11: Concrete Pumps | B11: 0 | D11: 0 | E11: Pump not deployed at GDI in March
A12: Maintenance & Spares | D12: 185000 | E12: Mostly used for Batching Plant spares
A13: Total Machinery Overhead | D13: =SUM(D7:D12) -> 340760
A15: 2. Fuel and Lubricant Overheads
A16: Description | B16: Consumption (Litres) | C16: TOTAL PRODUCTION (IN CuM.) | D16: AVERAGE FUEL CONSUMPTION (IN LITRES PER CuM.) | E16: Rate of Fuel (₹/Litre) | F16: Total Cost (₹) | G16: Fuel Cost per CuM. (₹)
A17: Diesel – TMs (Shared Resources, used interchangeably at both plants) | B17: 0 | C17: 1772 | D17: =B21/C17 -> 0.73363431 | E17: 88.05 | F17: =E17*B21 -> 114465 | G17: =F17/C17 -> 64.596501
A18: Diesel – JCB | B18: 1300
A19: Diesel – LOADER | B19: 0
A20: Diesel – DG | B20: 0
A21: Total Fuel Overhead | B21: =SUM(B17:B20) -> 1300
A23: 3. Raw Material Overheads
A24: Material | B24: Avg. Cost per MT (₹) | C24: Monthly Quantity Consumed (MT) | D24: Total Cost (₹) | E24: Raw Material Cost Per CuM. (₹) | F24: Remarks
A25: Cement | B25: 6619.99 | C25: 442.13 | D25: =B25*C25 -> 2926896.2 | E25: =D32/C17 -> 4279.95
A26: 20mm Aggregate | B26: =1280+5%*1280 -> 1344 | C26: 1011 | D26: =B26*C26 -> 1358784
A27: 10mm Aggregate | B27: =1245+5%*1245 -> 1307.25 | C27: 916 | D27: =B27*C27 -> 1197441
A28: Fine Aggregate | B28: =1235+5%*1235 -> 1296.75 | C28: 1406 | D28: =B28*C28 -> 1823230.5
A29: Fly Ash | B29: =1275+5%*1275 -> 1338.75 | C29: 207.3 | D29: =B29*C29 -> 277522.88
A30: Admixtures | B30: 53 | C30: 3.713 | D30: =B30*C30 -> 196.789
A31: Water Tanker | C31: 0 | D31: =B31*C31 -> 0
A32: Total Raw Material Overhead | D32: =SUM(D25:D31) -> 7584071.3
A34: 4. Manpower Overhead (Labour Expenses)
A35: Category | C35: No. of Persons | D35: Total Cost (₹) | E35: Details of Personnel Deployed | F35: Manpower Cost Per CuM. (₹)
A36: Maintenance & Electrical Team | C36: 0 | E36: Shared Resources amongst both plants, cost already considered in KRH | F36: =D43/C17 -> 22.573363
A37: Quality Team | C37: 0 | E37: Shared Resources amongst both plants, cost already considered in KRH
A38: Batching Plant Operator | C38: 1 | D38: 40000 | E38: Lovekush
A39: Production Supervision Team | C39: 0 | E39: Shared Resources amongst both plants, cost already considered in KRH
A40: Helper / Unskilled Labour | D40: 0 | E40: Shared Resources amongst both plants, cost already considered in KRH
A41: JCB & Loader Operator | E41: Deployed on part of the vendor
A42: Housekeeping / Office Staff | C42: 0 | E42: Not deployed
A43: Total Manpower Overhead | D43: =SUM(D36:D42) -> 40000
A45: 5. Electricity and Power Overheads
...
